Loading pytorch-gpu/py3/1.10.1
  Loading requirement: cuda/11.2 nccl/2.9.6-1-cuda cudnn/8.1.1.33-cuda gcc/8.5.0
    openmpi/4.1.1-cuda intel-mkl/2020.4 magma/2.5.4-cuda sox/14.4.2
/linkhome/rech/genkmw01/ujf38zl/.local/lib/python3.9/site-packages/torch/distributed/launch.py:181: FutureWarning: The module torch.distributed.launch is deprecated
and will be removed in future. Use torchrun.
Note that --use-env is set by default in torchrun.
If your script expects `--local-rank` argument to be set, please
change it to read from `os.environ['LOCAL_RANK']` instead. See 
https://pytorch.org/docs/stable/distributed.html#launch-utility for 
further instructions

  warnings.warn(
[2023-11-24 15:47:24,401] torch.distributed.run: [WARNING] 
[2023-11-24 15:47:24,401] torch.distributed.run: [WARNING] *****************************************
[2023-11-24 15:47:24,401] torch.distributed.run: [WARNING] Setting OMP_NUM_THREADS environment variable for each process to be 1 in default, to avoid your system being overloaded, please further tune the variable for optimal performance in your application as needed. 
[2023-11-24 15:47:24,401] torch.distributed.run: [WARNING] *****************************************
/gpfslocalsup/pub/anaconda-py3/2021.05/envs/pytorch-gpu-1.10.1+py3.9.7/lib/python3.9/site-packages/requests/__init__.py:102: RequestsDependencyWarning: urllib3 (1.26.9) or chardet (5.2.0)/charset_normalizer (2.0.12) doesn't match a supported version!
  warnings.warn("urllib3 ({}) or chardet ({})/charset_normalizer ({}) doesn't match a supported "
/gpfslocalsup/pub/anaconda-py3/2021.05/envs/pytorch-gpu-1.10.1+py3.9.7/lib/python3.9/site-packages/requests/__init__.py:102: RequestsDependencyWarning: urllib3 (1.26.9) or chardet (5.2.0)/charset_normalizer (2.0.12) doesn't match a supported version!
  warnings.warn("urllib3 ({}) or chardet ({})/charset_normalizer ({}) doesn't match a supported "
/gpfslocalsup/pub/anaconda-py3/2021.05/envs/pytorch-gpu-1.10.1+py3.9.7/lib/python3.9/site-packages/torchvision-0.11.0a0+e7ec7e2-py3.9-linux-x86_64.egg/torchvision/io/image.py:11: UserWarning: Failed to load image Python extension: /gpfs7kro/gpfslocalsup/pub/anaconda-py3/2021.05/envs/pytorch-gpu-1.10.1+py3.9.7/lib/python3.9/site-packages/torchvision-0.11.0a0+e7ec7e2-py3.9-linux-x86_64.egg/torchvision/image.so: undefined symbol: _ZN5torch3jit17parseSchemaOrNameERKNSt7__cxx1112basic_stringIcSt11char_traitsIcESaIcEEE
  warn(f"Failed to load image Python extension: {e}")
/gpfslocalsup/pub/anaconda-py3/2021.05/envs/pytorch-gpu-1.10.1+py3.9.7/lib/python3.9/site-packages/torchvision-0.11.0a0+e7ec7e2-py3.9-linux-x86_64.egg/torchvision/io/image.py:11: UserWarning: Failed to load image Python extension: /gpfs7kro/gpfslocalsup/pub/anaconda-py3/2021.05/envs/pytorch-gpu-1.10.1+py3.9.7/lib/python3.9/site-packages/torchvision-0.11.0a0+e7ec7e2-py3.9-linux-x86_64.egg/torchvision/image.so: undefined symbol: _ZN5torch3jit17parseSchemaOrNameERKNSt7__cxx1112basic_stringIcSt11char_traitsIcESaIcEEE
  warn(f"Failed to load image Python extension: {e}")
usage: train.py [-h] [--task {img_based,video_based,vp_vqa}] --base_folder
                BASE_FOLDER --params PARAMS [--weight WEIGHT] [--fp16] [--ddp]
                [--cudnn] [--local_rank LOCAL_RANK] [--local-rank LOCAL_RANK]
usage: train.py [-h] [--task {img_based,video_based,vp_vqa}] --base_folder
                BASE_FOLDER --params PARAMS [--weight WEIGHT] [--fp16] [--ddp]
                [--cudnn] [--local_rank LOCAL_RANK] [--local-rank LOCAL_RANK]
train.py: error: argument --local_rank: expected one argument
train.py: error: argument --local_rank: expected one argument
[2023-11-24 15:48:09,478] torch.distributed.elastic.multiprocessing.api: [ERROR] failed (exitcode: 2) local_rank: 0 (pid: 2008040) of binary: /gpfslocalsup/pub/anaconda-py3/2021.05/envs/pytorch-gpu-1.10.1+py3.9.7/bin/python
Traceback (most recent call last):
  File "/gpfslocalsup/pub/anaconda-py3/2021.05/envs/pytorch-gpu-1.10.1+py3.9.7/lib/python3.9/runpy.py", line 197, in _run_module_as_main
    return _run_code(code, main_globals, None,
  File "/gpfslocalsup/pub/anaconda-py3/2021.05/envs/pytorch-gpu-1.10.1+py3.9.7/lib/python3.9/runpy.py", line 87, in _run_code
    exec(code, run_globals)
  File "/linkhome/rech/genkmw01/ujf38zl/.local/lib/python3.9/site-packages/torch/distributed/launch.py", line 196, in <module>
    main()
  File "/linkhome/rech/genkmw01/ujf38zl/.local/lib/python3.9/site-packages/torch/distributed/launch.py", line 192, in main
    launch(args)
  File "/linkhome/rech/genkmw01/ujf38zl/.local/lib/python3.9/site-packages/torch/distributed/launch.py", line 177, in launch
    run(args)
  File "/linkhome/rech/genkmw01/ujf38zl/.local/lib/python3.9/site-packages/torch/distributed/run.py", line 797, in run
    elastic_launch(
  File "/linkhome/rech/genkmw01/ujf38zl/.local/lib/python3.9/site-packages/torch/distributed/launcher/api.py", line 134, in __call__
    return launch_agent(self._config, self._entrypoint, list(args))
  File "/linkhome/rech/genkmw01/ujf38zl/.local/lib/python3.9/site-packages/torch/distributed/launcher/api.py", line 264, in launch_agent
    raise ChildFailedError(
torch.distributed.elastic.multiprocessing.errors.ChildFailedError: 
============================================================
scripts/train.py FAILED
------------------------------------------------------------
Failures:
[1]:
  time      : 2023-11-24_15:48:09
  host      : r10i3n4-ib0
  rank      : 1 (local_rank: 1)
  exitcode  : 2 (pid: 2008041)
  error_file: <N/A>
  traceback : To enable traceback see: https://pytorch.org/docs/stable/elastic/errors.html
------------------------------------------------------------
Root Cause (first observed failure):
[0]:
  time      : 2023-11-24_15:48:09
  host      : r10i3n4-ib0
  rank      : 0 (local_rank: 0)
  exitcode  : 2 (pid: 2008040)
  error_file: <N/A>
  traceback : To enable traceback see: https://pytorch.org/docs/stable/elastic/errors.html
============================================================
